Workbook

Sheet core_2
A2: Timestamp | B2: Participant ID: | C2: Self assesment_Mean | D2: Self Assesment_sum | E2: Sum( reversed negative values) | F2: Personal positive | G2: Personal negative | H2: Social Posiitve | I2: Social negative | J2: TA Time_NQ | K2: TA Time_q | L2: Assembly time_No question | M2: Assembly time_ question | N2: Robot N_task_No question | O2: Robot N_task_ question | P2: Mental_NQ | Q2: Mental_Q | R2: Physical_NQ | S2: Physical_Q | T2: Temporal_NQ | U2: Temporal_Q | V2: Performance_NQ | W2: Performance_Q | X2: Effort_NQ | Y2: Effort_Q | Z2: Frustration_NQ | AA2: Frustration_Q | AB2: Satisfaction_NQ | AC2: Satisfaction_Q | AD2: Fairness_NQ | AE2: Fairness_Q | AF2: Efficency_NQ | AG2: Efficency_Q | AH2: TA_Satis_NQ | AI2: TA_Satis_Q | AJ2: Willingness_NQ | AK2: Willingness_Q | AL2: TA_Difficulty_NQ | AM2: TA_Difficulty_Q
A3: 45909.445 | B3: p11 | C3: =Form_Responses[[#This Row],[SUM]]/10 -> 3.1 | D3: =SUM(Form_Responses[[#This Row],[1- I can always manage to solve difficult problems if I try hard enough.]:[10- I can usually handle whatever comes my way.]]) -> 31 | E3: =60+SUM(Form_Responses[[#This Row],[11- Robots are necessary because they can do jobs that are too hard or too dangerous for people ]:[15- Robots are a good thing for society, because they help people]])-SUM(Form_Responses[[#This Row],[16- Robots may make us even lazier ]:[20- Unregulated use of robotics can lead to societal upheavals]]) -> 64 | F3: =SUM(Form_Responses[[#This Row],[1- I can trust persons and organizations related to development of robots ]:[5- If robots had emotions, I would be able to be friend with them]]) -> 10 | G3: =SUM(Form_Responses[[#This Row],[6- I would feel uneasy if I was given a job where I had to use robots]:[10- I don’t want a robot to touch me]]) -> 9 | H3: =SUM(Form_Responses[[#This Row],[11- Robots are necessary because they can do jobs that are too hard or too dangerous for people ]:[15- Robots are a good thing for society, because they help people]]) -> 22 | I3: =SUM(Form_Responses[[#This Row],[16- Robots may make us even lazier ]:[20- Unregulated use of robotics can lead to societal upheavals]]) -> 18 | J3: =TA_NQY!E8+TA_NQO!E8 -> 109 | K3: =TA_QY!E8+TA_QO!E8 -> 126 | L3: 347 | M3: 581 | N3: 19 | O3: 21 | P3: 4 | Q3: 10 | R3: 7 | S3: 9 | T3: 6 | U3: 8 | V3: 10 | W3: 10 | X3: 7 | Y3: 9 | Z3: 6 | AA3: 9 | AB3: 10 | AC3: 9 | AD3: 10 | AE3: 8 | AF3: 9 | AG3: 9 | AH3: 9 | AI3: 9 | AJ3: 10 | AK3: 10 | AL3: 4 | AM3: 10
A4: 45909.613 | B4: P14 | C4: =Form_Responses[[#This Row],[SUM]]/10 -> 3.3 | D4: =SUM(Form_Responses[[#This Row],[1- I can always manage to solve difficult problems if I try hard enough.]:[10- I can usually handle whatever comes my way.]]) -> 33 | E4: =60+SUM(Form_Responses[[#This Row],[11- Robots are necessary because they can do jobs that are too hard or too dangerous for people ]:[15- Robots are a good thing for society, because they help people]])-SUM(Form_Responses[[#This Row],[16- Robots may make us even lazier ]:[20- Unregulated use of robotics can lead to societal upheavals]]) -> 64 | F4: =SUM(Form_Responses[[#This Row],[1- I can trust persons and organizations related to development of robots ]:[5- If robots had emotions, I would be able to be friend with them]]) -> 17 | G4: =SUM(Form_Responses[[#This Row],[6- I would feel uneasy if I was given a job where I had to use robots]:[10- I don’t want a robot to touch me]]) -> 8 | H4: =SUM(Form_Responses[[#This Row],[11- Robots are necessary because they can do jobs that are too hard or too dangerous for people ]:[15- Robots are a good thing for society, because they help people]]) -> 23 | I4: =SUM(Form_Responses[[#This Row],[16- Robots may make us even lazier ]:[20- Unregulated use of robotics can lead to societal upheavals]]) -> 19 | J4: =TA_NQY!E11+TA_NQO!E11 -> 249 | K4: =TA_QY!E11+TA_QO!E11 -> 139 | L4: 311 | M4: 374 | N4: 19 | O4: 22 | P4: 2 | Q4: 5 | R4: 2 | S4: 3 | T4: 2 | U4: 4 | V4: 8 | W4: 7 | X4: 3 | Y4: 4 | Z4: 1 | AA4: 1 | AB4: 9 | AC4: 9 | AD4: 6 | AE4: 8 | AF4: 4 | AG4: 8 | AH4: 7 | AI4: 8 | AJ4: 10 | AK4: 8 | AL4: 4 | AM4: 3
A5: 45909.663 | B5: P15 | C5: =Form_Responses[[#This Row],[SUM]]/10 -> 3.4 | D5: =SUM(Form_Responses[[#This Row],[1- I can always manage to solve difficult problems if I try hard enough.]:[10- I can usually handle whatever comes my way.]]) -> 34 | E5: =60+SUM(Form_Responses[[#This Row],[11- Robots are necessary because they can do jobs that are too hard or too dangerous for people ]:[15- Robots are a good thing for society, because they help people]])-SUM(Form_Responses[[#This Row],[16- Robots may make us even lazier ]:[20- Unregulated use of robotics can lead to societal upheavals]]) -> 64 | F5: =SUM(Form_Responses[[#This Row],[1- I can trust persons and organizations related to development of robots ]:[5- If robots had emotions, I would be able to be friend with them]]) -> 14 | G5: =SUM(Form_Responses[[#This Row],[6- I would feel uneasy if I was given a job where I had to use robots]:[10- I don’t want a robot to touch me]]) -> 9 | H5: =SUM(Form_Responses[[#This Row],[11- Robots are necessary because they can do jobs that are too hard or too dangerous for people ]:[15- Robots are a good thing for society, because they help people]]) -> 22 | I5: =SUM(Form_Responses[[#This Row],[16- Robots may make us even lazier ]:[20- Unregulated use of robotics can lead to societal upheavals]]) -> 18 | J5: =TA_NQY!E12+TA_NQO!E12 -> 127 | K5: =TA_QY!E12+TA_QO!E12 -> 171 | L5: 244 | M5: 668 | N5: 10 | O5: 17 | P5: 3 | Q5: 7 | R5: 6 | S5: 4 | T5: 6 | U5: 5 | V5: 10 | W5: 6 | X5: 6 | Y5: 6 | Z5: 3 | AA5: 5 | AB5: 9 | AC5: 7 | AD5: 10 | AE5: 10 | AF5: 8 | AG5: 7 | AH5: 8 | AI5: 6 | AJ5: 10 | AK5: 10 | AL5: 6 | AM5: 7
A6: 45909.707 | B6: P16 | C6: =Form_Responses[[#This Row],[SUM]]/10 -> 3.9 | D6: =SUM(Form_Responses[[#This Row],[1- I can always manage to solve difficult problems if I try hard enough.]:[10- I can usually handle whatever comes my way.]]) -> 39 | E6: =60+SUM(Form_Responses[[#This Row],[11- Robots are necessary because they can do jobs that are too hard or too dangerous for people ]:[15- Robots are a good thing for society, because they help people]])-SUM(Form_Responses[[#This Row],[16- Robots may make us even lazier ]:[20- Unregulated use of robotics can lead to societal upheavals]]) -> 72 | F6: =SUM(Form_Responses[[#This Row],[1- I can trust persons and organizations related to development of robots ]:[5- If robots had emotions, I would be able to be friend with them]]) -> 16 | G6: =SUM(Form_Responses[[#This Row],[6- I would feel uneasy if I was given a job where I had to use robots]:[10- I don’t want a robot to touch me]]) -> 8 | H6: =SUM(Form_Responses[[#This Row],[11- Robots are necessary because they can do jobs that are too hard or too dangerous for people ]:[15- Robots are a good thing for society, because they help people]]) -> 19 | I6: =SUM(Form_Responses[[#This Row],[16- Robots may make us even lazier ]:[20- Unregulated use of robotics can lead to societal upheavals]]) -> 7 | J6: =TA_NQY!E13+TA_NQO!E13 -> 137 | K6: =TA_QY!E13+TA_QO!E13 -> 510 | L6: 305 | M6: 433 | N6: 15 | O6: 19 | P6: 1 | Q6: 6 | R6: 5 | S6: 6 | T6: 2 | U6: 8 | V6: 10 | W6: 9 | X6: 6 | Y6: 7 | Z6: 2 | AA6: 5 | AB6: 9 | AC6: 8 | AD6: 8 | AE6: 7 | AF6: 8 | AG6: 4 | AH6: 8 | AI6: 6 | AJ6: 10 | AK6: 10 | AL6: 8 | AM6: 8
A7: 45910.585 | B7: P18 | C7: =Form_Responses[[#This Row],[SUM]]/10 -> 3 | D7: =SUM(Form_Responses[[#This Row],[1- I can always manage to solve difficult problems if I try hard enough.]:[10- I can usually handle whatever comes my way.]]) -> 30 | E7: =60+SUM(Form_Responses[[#This Row],[11- Robots are necessary because they can do jobs that are too hard or too dangerous for people ]:[15- Robots are a good thing for society, because they help people]])-SUM(Form_Responses[[#This Row],[16- Robots may make us even lazier ]:[20- Unregulated use of robotics can lead to societal upheavals]]) -> 71 | F7: =SUM(Form_Responses[[#This Row],[1- I can trust persons and organizations related to development of robots ]:[5- If robots had emotions, I would be able to be friend with them]]) -> 20 | G7: =SUM(Form_Responses[[#This Row],[6- I would feel uneasy if I was given a job where I had to use robots]:[10- I don’t want a robot to touch me]]) -> 9 | H7: =SUM(Form_Responses[[#This Row],[11- Robots are necessary because they can do jobs that are too hard or too dangerous for people ]:[15- Robots are a good thing for society, because they help people]]) -> 21 | I7: =SUM(Form_Responses[[#This Row],[16- Robots may make us even lazier ]:[20- Unregulated use of robotics can lead to societal upheavals]]) -> 10 | J7: =TA_NQY!E15+TA_NQO!E15 -> 407 | K7: =TA_QY!E15+TA_QO!E15 -> 624 | L7: 250 | M7: 356 | N7: 13 | O7: 19 | P7: 5 | Q7: 8 | R7: 5 | S7: 4 | T7: 6 | U7: 8 | V7: 9 | W7: 9 | X7: 5 | Y7: 7 | Z7: 2 | AA7: 2 | AB7: 9 | AC7: 9 | AD7: 8 | AE7: 7 | AF7: 7 | AG7: 8 | AH7: 9 | AI7: 8 | AJ7: 9 | AK7: 9 | AL7: 8 | AM7: 8
A8: 45910.692 | B8: P10 | C8: 3.1 | D8: 31 | E8: 64 | F8: 10 | G8: 9 | H8: 22 | I8: 18 | J8: 280 | K8: 470 | L8: 269 | M8: 376 | N8: 15 | O8: 22 | P8: 2 | Q8: 4 | R8: 5 | S8: 3 | T8: 5 | U8: 3 | V8: 10 | W8: 10 | X8: 6 | Y8: 2 | Z8: 1 | AA8: 1 | AB8: 10 | AC8: 10 | AD8: 10 | AE8: 10 | AF8: 10 | AG8: 7 | AH8: 7 | AI8: 10 | AJ8: 10 | AK8: 10 | AL8: 3 | AM8: 3
A9: 45912.401 | B9: P20 | C9: =Form_Responses[[#This Row],[SUM]]/10 -> 3.9 | D9: =SUM(Form_Responses[[#This Row],[1- I can always manage to solve difficult problems if I try hard enough.]:[10- I can usually handle whatever comes my way.]]) -> 39 | E9: =60+SUM(Form_Responses[[#This Row],[11- Robots are necessary because they can do jobs that are too hard or too dangerous for people ]:[15- Robots are a good thing for society, because they help people]])-SUM(Form_Responses[[#This Row],[16- Robots may make us even lazier ]:[20- Unregulated use of robotics can lead to societal upheavals]]) -> 64 | F9: =SUM(Form_Responses[[#This Row],[1- I can trust persons and organizations related to development of robots ]:[5- If robots had emotions, I would be able to be friend with them]]) -> 20 | G9: =SUM(Form_Responses[[#This Row],[6- I would feel uneasy if I was given a job where I had to use robots]:[10- I don’t want a robot to touch me]]) -> 17 | H9: =SUM(Form_Responses[[#This Row],[11- Robots are necessary because they can do jobs that are too hard or too dangerous for people ]:[15- Robots are a good thing for society, because they help people]]) -> 21 | I9: =SUM(Form_Responses[[#This Row],[16- Robots may make us even lazier ]:[20- Unregulated use of robotics can lead to societal upheavals]]) -> 17 | J9: =TA_NQY!E18+TA_NQO!E18 -> 125 | K9: =TA_QY!E18+TA_QO!E18 -> 413 | L9: 272 | M9: 413 | N9: 15 | O9: 18 | P9: 1 | Q9: 4 | R9: 1 | S9: 2 | T9: 3 | U9: 5 | V9: 10 | W9: 8 | X9: 3 | Y9: 7 | Z9: 3 | AA9: 4 | AB9: 10 | AC9: 8 | AD9: 10 | AE9: 6 | AF9: 10 | AG9: 3 | AH9: 10 | AI9: 4 | AJ9: 10 | AK9: 10 | AL9: 7 | AM9: 7
A10: 45912.494 | B10: P22 | C10: =Form_Responses[[#This Row],[SUM]]/10 -> 3 | D10: =SUM(Form_Responses[[#This Row],[1- I can always manage to solve difficult problems if I try hard enough.]:[10- I can usually handle whatever comes my way.]]) -> 30 | E10: =60+SUM(Form_Responses[[#This Row],[11- Robots are necessary because they can do jobs that are too hard or too dangerous for people ]:[15- Robots are a good thing for society, because they help people]])-SUM(Form_Responses[[#This Row],[16- Robots may make us even lazier ]:[20- Unregulated use of robotics can lead to societal upheavals]]) -> 62 | F10: =SUM(Form_Responses[[#This Row],[1- I can trust persons and organizations related to development of robots ]:[5- If robots had emotions, I would be able to be friend with them]]) -> 8 | G10: =SUM(Form_Responses[[#This Row],[6- I would feel uneasy if I was given a job where I had to use robots]:[10- I don’t want a robot to touch me]]) -> 7 | H10: =SUM(Form_Responses[[#This Row],[11- Robots are necessary because they can do jobs that are too hard or too dangerous for people ]:[15- Robots are a good thing for society, because they help people]]) -> 23 | I10: =SUM(Form_Responses[[#This Row],[16- Robots may make us even lazier ]:[20- Unregulated use of robotics can lead to societal upheavals]]) -> 21 | J10: =TA_NQY!E20+TA_NQO!E20 -> 254 | K10: =TA_QY!E20+TA_QO!E20 -> 406 | L10: 346 | M10: 396 | N10: 20 | O10: 22 | P10: 2 | Q10: 3 | R10: 2 | S10: 3 | T10: 2 | U10: 5 | V10: 9 | W10: 9 | X10: 3 | Y10: 6 | Z10: 1 | AA10: 1 | AB10: 9 | AC10: 9 | AD10: 8 | AE10: 7 | AF10: 8 | AG10: 7 | AH10: 8 | AI10: 7 | AJ10: 10 | AK10: 10 | AL10: 2 | AM10: 2
A11: 45912.72 | B11: P26 | C11: =Form_Responses[[#This Row],[SUM]]/10 -> 3.4 | D11: =SUM(Form_Responses[[#This Row],[1- I can always manage to solve difficult problems if I try hard enough.]:[10- I can usually handle whatever comes my way.]]) -> 34 | E11: =60+SUM(Form_Responses[[#This Row],[11- Robots are necessary because they can do jobs that are too hard or too dangerous for people ]:[15- Robots are a good thing for society, because they help people]])-SUM(Form_Responses[[#This Row],[16- Robots may make us even lazier ]:[20- Unregulated use of robotics can lead to societal upheavals]]) -> 73 | F11: =SUM(Form_Responses[[#This Row],[1- I can trust persons and organizations related to development of robots ]:[5- If robots had emotions, I would be able to be friend with them]]) -> 15 | G11: =SUM(Form_Responses[[#This Row],[6- I would feel uneasy if I was given a job where I had to use robots]:[10- I don’t want a robot to touch me]]) -> 6 | H11: =SUM(Form_Responses[[#This Row],[11- Robots are necessary because they can do jobs that are too hard or too dangerous for people ]:[15- Robots are a good thing for society, because they help people]]) -> 24 | I11: =SUM(Form_Responses[[#This Row],[16- Robots may make us even lazier ]:[20- Unregulated use of robotics can lead to societal upheavals]]) -> 11 | J11: =TA_NQY!E24+TA_NQO!E24 -> 64 | K11: =TA_QY!E24+TA_QO!E24 -> 158 | L11: 305 | M11: 410 | N11: 16 | O11: 16 | P11: 8 | Q11: 7 | R11: 8 | S11: 9 | T11: 9 | U11: 8 | V11: 9 | W11: 10 | X11: 8 | Y11: 7 | Z11: 1 | AA11: 2 | AB11: 9 | AC11: 9 | AD11: 10 | AE11: 10 | AF11: 10 | AG11: 9 | AH11: 10 | AI11: 9 | AJ11: 9 | AK11: 9 | AL11: 3 | AM11: 4
A12: 45915.492 | B12: P27 | C12: =Form_Responses[[#This Row],[SUM]]/10 -> 3.2 | D12: =SUM(Form_Responses[[#This Row],[1- I can always manage to solve difficult problems if I try hard enough.]:[10- I can usually handle whatever comes my way.]]) -> 32 | E12: =60+SUM(Form_Responses[[#This Row],[11- Robots are necessary because they can do jobs that are too hard or too dangerous for people ]:[15- Robots are a good thing for society, because they help people]])-SUM(Form_Responses[[#This Row],[16- Robots may make us even lazier ]:[20- Unregulated use of robotics can lead to societal upheavals]]) -> 73 | F12: =SUM(Form_Responses[[#This Row],[1- I can trust persons and organizations related to development of robots ]:[5- If robots had emotions, I would be able to be friend with them]]) -> 21 | G12: =SUM(Form_Responses[[#This Row],[6- I would feel uneasy if I was given a job where I had to use robots]:[10- I don’t want a robot to touch me]]) -> 8 | H12: =SUM(Form_Responses[[#This Row],[11- Robots are necessary because they can do jobs that are too hard or too dangerous for people ]:[15- Robots are a good thing for society, because they help people]]) -> 24 | I12: =SUM(Form_Responses[[#This Row],[16- Robots may make us even lazier ]:[20- Unregulated use of robotics can lead to societal upheavals]]) -> 11 | J12: =TA_NQY!E25+TA_NQO!E25 -> 530 | K12: =TA_QY!E25+TA_QO!E25 -> 139 | L12: 295 | M12: 412 | N12: 17 | O12: 22 | P12: 2 | Q12: 6 | R12: 4 | S12: 2 | T12: 2 | U12: 5 | V12: 10 | W12: 10 | X12: 3 | Y12: 4 | Z12: 1 | AA12: 2 | AB12: 9 | AC12: 10 | AD12: 10 | AE12: 10 | AF12: 8 | AG12: 9 | AH12: 8 | AI12: 9 | AJ12: 9 | AK12: 10 | AL12: 6 | AM12: 2
A13: 45915.572 | B13: P28 | C13: =Form_Responses[[#This Row],[SUM]]/10 -> 2.9 | D13: =SUM(Form_Responses[[#This Row],[1- I can always manage to solve difficult problems if I try hard enough.]:[10- I can usually handle whatever comes my way.]]) -> 29 | E13: =60+SUM(Form_Responses[[#This Row],[11- Robots are necessary because they can do jobs that are too hard or too dangerous for people ]:[15- Robots are a good thing for society, because they help people]])-SUM(Form_Responses[[#This Row],[16- Robots may make us even lazier ]:[20- Unregulated use of robotics can lead to societal upheavals]]) -> 70 | F13: =SUM(Form_Responses[[#This Row],[1- I can trust persons and organizations related to development of robots ]:[5- If robots had emotions, I would be able to be friend with them]]) -> 22 | G13: =SUM(Form_Responses[[#This Row],[6- I would feel uneasy if I was given a job where I had to use robots]:[10- I don’t want a robot to touch me]]) -> 8 | H13: =SUM(Form_Responses[[#This Row],[11- Robots are necessary because they can do jobs that are too hard or too dangerous for people ]:[15- Robots are a good thing for society, because they help people]]) -> 24 | I13: =SUM(Form_Responses[[#This Row],[16- Robots may make us even lazier ]:[20- Unregulated use of robotics can lead to societal upheavals]]) -> 14 | J13: =TA_NQY!E26+TA_NQO!E26 -> 254 | K13: =TA_QY!E26+TA_QO!E26 -> 497 | L13: 220 | M13: 326 | N13: 12 | O13: 18 | P13: 3 | Q13: 6 | R13: 4 | S13: 4 | T13: 3 | U13: 7 | V13: 10 | W13: 9 | X13: 3 | Y13: 6 | Z13: 2 | AA13: 1 | AB13: 6 | AC13: 8 | AD13: 7 | AE13: 8 | AF13: 8 | AG13: 7 | AH13: 7 | AI13: 7 | AJ13: 9 | AK13: 9 | AL13: 3 | AM13: 6
A14: 45916.481 | B14: P29 | C14: =Form_Responses[[#This Row],[SUM]]/10 -> 3 | D14: =SUM(Form_Responses[[#This Row],[1- I can always manage to solve difficult problems if I try hard enough.]:[10- I can usually handle whatever comes my way.]]) -> 30 | E14: =60+SUM(Form_Responses[[#This Row],[11- Robots are necessary because they can do jobs that are too hard or too dangerous for people ]:[15- Robots are a good thing for society, because they help people]])-SUM(Form_Responses[[#This Row],[16- Robots may make us even lazier ]:[20- Unregulated use of robotics can lead to societal upheavals]]) -> 69 | F14: =SUM(Form_Responses[[#This Row],[1- I can trust persons and organizations related to development of robots ]:[5- If robots had emotions, I would be able to be friend with them]]) -> 19 | G14: =SUM(Form_Responses[[#This Row],[6- I would feel uneasy if I was given a job where I had to use robots]:[10- I don’t want a robot to touch me]]) -> 7 | H14: =SUM(Form_Responses[[#This Row],[11- Robots are necessary because they can do jobs that are too hard or too dangerous for people ]:[15- Robots are a good thing for society, because they help people]]) -> 24 | I14: =SUM(Form_Responses[[#This Row],[16- Robots may make us even lazier ]:[20- Unregulated use of robotics can lead to societal upheavals]]) -> 15 | J14: =TA_NQY!E27+TA_NQO!E27 -> 454 | K14: =TA_QY!E27+TA_QO!E27 -> 159 | L14: 240 | M14: 260 | N14: 11 | O14: 12 | P14: 2 | Q14: 4 | R14: 2 | S14: 2 | T14: 3 | U14: 5 | V14: 10 | W14: 10 | X14: 3 | Y14: 5 | Z14: 1 | AA14: 1 | AB14: 10 | AC14: 10 | AD14: 10 | AE14: 10 | AF14: 10 | AG14: 10 | AH14: 10 | AI14: 10 | AJ14: 10 | AK14: 10 | AL14: 4 | AM14: 4
A15: 45916.566 | B15: P30 | C15: =Form_Responses[[#This Row],[SUM]]/10 -> 2.8 | D15: =SUM(Form_Responses[[#This Row],[1- I can always manage to solve difficult problems if I try hard enough.]:[10- I can usually handle whatever comes my way.]]) -> 28 | E15: =60+SUM(Form_Responses[[#This Row],[11- Robots are necessary because they can do jobs that are too hard or too dangerous for people ]:[15- Robots are a good thing for society, because they help people]])-SUM(Form_Responses[[#This Row],[16- Robots may make us even lazier ]:[20- Unregulated use of robotics can lead to societal upheavals]]) -> 65 | F15: =SUM(Form_Responses[[#This Row],[1- I can trust persons and organizations related to development of robots ]:[5- If robots had emotions, I would be able to be friend with them]]) -> 21 | G15: =SUM(Form_Responses[[#This Row],[6- I would feel uneasy if I was given a job where I had to use robots]:[10- I don’t want a robot to touch me]]) -> 8 | H15: =SUM(Form_Responses[[#This Row],[11- Robots are necessary because they can do jobs that are too hard or too dangerous for people ]:[15- Robots are a good thing for society, because they help people]]) -> 22 | I15: =SUM(Form_Responses[[#This Row],[16- Robots may make us even lazier ]:[20- Unregulated use of robotics can lead to societal upheavals]]) -> 17 | J15: =TA_NQY!E28+TA_NQO!E28 -> 276 | K15: =TA_QY!E28+TA_QO!E28 -> 378 | L15: 336 | M15: 420 | N15: 16 | O15: 20 | P15: 4 | Q15: 7 | R15: 3 | S15: 3 | T15: 6 | U15: 5 | V15: 10 | W15: 10 | X15: 6 | Y15: 6 | Z15: 2 | AA15: 7 | AB15: 9 | AC15: 8 | AD15: 7 | AE15: 9 | AF15: 8 | AG15: 9 | AH15: 8 | AI15: 9 | AJ15: 10 | AK15: 9 | AL15: 5 | AM15: 3
A16: 45917.608 | B16: P34 | C16: =Form_Responses[[#This Row],[SUM]]/10 -> 3.6 | D16: =SUM(Form_Responses[[#This Row],[1- I can always manage to solve difficult problems if I try hard enough.]:[10- I can usually handle whatever comes my way.]]) -> 36 | E16: =60+SUM(Form_Responses[[#This Row],[11- Robots are necessary because they can do jobs that are too hard or too dangerous for people ]:[15- Robots are a good thing for society, because they help people]])-SUM(Form_Responses[[#This Row],[16- Robots may make us even lazier ]:[20- Unregulated use of robotics can lead to societal upheavals]]) -> 78 | F16: =SUM(Form_Responses[[#This Row],[1- I can trust persons and organizations related to development of robots ]:[5- If robots had emotions, I would be able to be friend with them]]) -> 21 | G16: =SUM(Form_Responses[[#This Row],[6- I would feel uneasy if I was given a job where I had to use robots]:[10- I don’t want a robot to touch me]]) -> 9 | H16: =SUM(Form_Responses[[#This Row],[11- Robots are necessary because they can do jobs that are too hard or too dangerous for people ]:[15- Robots are a good thing for society, because they help people]]) -> 25 | I16: =SUM(Form_Responses[[#This Row],[16- Robots may make us even lazier ]:[20- Unregulated use of robotics can lead to societal upheavals]]) -> 7 | J16: =TA_NQY!E32+TA_NQO!E32 -> 202 | K16: =TA_QY!E32+TA_QO!E32 -> 564 | L16: 236 | M16: 373 | N16: 13 | O16: 17 | P16: 2 | Q16: 7 | R16: 3 | S16: 3 | T16: 5 | U16: 7 | V16: 8 | W16: 8 | X16: 5 | Y16: 3 | Z16: 2 | AA16: 2 | AB16: 7 | AC16: 8 | AD16: 8 | AE16: 9 | AF16: 6 | AG16: 7 | AH16: 5 | AI16: 6 | AJ16: 9 | AK16: 9 | AL16: 7 | AM16: 7
A17: 45918.561 | B17: P36 | C17: =Form_Responses[[#This Row],[SUM]]/10 -> 3.3 | D17: =SUM(Form_Responses[[#This Row],[1- I can always manage to solve difficult problems if I try hard enough.]:[10- I can usually handle whatever comes my way.]]) -> 33 | E17: =60+SUM(Form_Responses[[#This Row],[11- Robots are necessary because they can do jobs that are too hard or too dangerous for people ]:[15- Robots are a good thing for society, because they help people]])-SUM(Form_Responses[[#This Row],[16- Robots may make us even lazier ]:[20- Unregulated use of robotics can lead to societal upheavals]]) -> 57 | F17: =SUM(Form_Responses[[#This Row],[1- I can trust persons and organizations related to development of robots ]:[5- If robots had emotions, I would be able to be friend with them]]) -> 18 | G17: =SUM(Form_Responses[[#This Row],[6- I would feel uneasy if I was given a job where I had to use robots]:[10- I don’t want a robot to touch me]]) -> 12 | H17: =SUM(Form_Responses[[#This Row],[11- Robots are necessary because they can do jobs that are too hard or too dangerous for people ]:[15- Robots are a good thing for society, because they help people]]) -> 18 | I17: =SUM(Form_Responses[[#This Row],[16- Robots may make us even lazier ]:[20- Unregulated use of robotics can lead to societal upheavals]]) -> 21 | J17: =TA_NQY!E34+TA_NQO!E34 -> 177 | K17: =TA_QY!E34+TA_QO!E34 -> 447 | L17: 345 | M17: 386 | N17: 20 | O17: 22 | P17: 1 | Q17: 6 | R17: 5 | S17: 6 | T17: 2 | U17: 7 | V17: 7 | W17: 5 | X17: 3 | Y17: 4 | Z17: 2 | AA17: 1 | AB17: 7 | AC17: 6 | AD17: 7 | AE17: 6 | AF17: 8 | AG17: 7 | AH17: 7 | AI17: 7 | AJ17: 10 | AK17: 9 | AL17: 8 | AM17: 9
B19: average: | C19: =AVERAGE(C3:C17) -> 3.26 | D19: =AVERAGE(D3:D17) -> 32.6 | E19: =AVERAGE(E3:E17) -> 67.333333 | F19: =AVERAGE(F3:F17) -> 16.8 | G19: =AVERAGE(G3:G17) -> 8.9333333 | H19: =AVERAGE(H3:H17) -> 22.266667 | I19: =AVERAGE(I3:I17) -> 14.933333 | J19: =AVERAGE(J3:J17) -> 243 | ... AM19: =AVERAGE(AM3:AM17) -> 5.5333333
B20: SD: | C20: =_xlfn.STDEV.S(C3:C17) -> 0.33551666 | D20: =_xlfn.STDEV.S(D3:D17) -> 3.3551666 | E20: =_xlfn.STDEV.S(E3:E17) -> 5.4728768 | F20: =_xlfn.STDEV.S(F3:F17) -> 4.5387223 | G20: =_xlfn.STDEV.S(G3:G17) -> 2.6040262 | H20: =_xlfn.STDEV.S(H3:H17) -> 1.9444671 | I20: =_xlfn.STDEV.S(I3:I17) -> 4.6975171 | J20: =_xlfn.STDEV.S(J3:J17) -> 133.94348 | ... AM20: =_xlfn.STDEV.S(AM3:AM17) -> 2.6690466

Sheet pattern_abnormal
B1: Demographics | G1: Nasa TLX | L1: Nasa TlX | Z1: Post experiment
A2: Timestamp | B2: Participant ID: | C2: Self_Sum | D2: Robot_sum | E2: Assembly time | F2: Assembly time with question | G2: Robot N_task | H2: Robot N_task With question | I2: Mental | J2: Mental_q | K2: Physical | L2: Physical_q | M2: Temporal | N2: Temporal2 | O2: successful | P2: successful 2 | Q2: Effort | R2: Effort2 | S2: Frustration | T2: Frustration 2 | U2: Satisfaction | V2: Satisfaction2 | W2: Fairness | X2: Fairness2 | Y2: Efficency | Z2: Efficency2 | AA2: TA_satis | AB2: TA_satis2 | AC2: Willingness | AD2: Willingness2 | AE2: TA_diffi | AF2: TA_diffi2 | AG2: 1- What factors influenced how you assigned tasks between yourself and the robot? (Select all that apply) | AH2: 2- How did you decide whether to assign a task to yourself or the robot? | AI2: 3- What were your thoughts about the robot’s capabilities? | AJ2: 4- Did you feel the robot was better at any tasks than you? | AK2: 5- Did the collaboration feel balanced? | AL2: 6- Do you think if the robot was more capable you would allocate more tasks to it? | AM2: 7- Did you consider yourself and the robot as a team? Or did you feel you are the lead of it? | AN2: 8- What qualities of the robot influenced your allocation decisions? | AO2: 9- Did your opinion of the robot change during the task? | AP2: 10- If you could reallocate the tasks after this experience, what would you change and why?
A3: in the second experiment, without Q got chilled | B3: P12 | C3: 39 | D3: 64 | E3: =TA_NQY!F9+TA_NQO!F9 -> 341 | F3: 301 | G3: =TA_NQY!G9+TA_NQO!G9 -> 20 | H3: 19 | I3: 1 | J3: 6 | K3: 2 | L3: 3 | M3: 3 | N3: 7 | O3: 10 | P3: 9 | Q3: 2 | R3: 8 | S3: 1 | T3: 6 | U3: 10 | V3: 9 | W3: 10 | X3: 9 | Y3: 10 | Z3: 8 | AA3: 10 | AB3: 9 | AC3: 10 | AD3: 10 | AE3: 2 | AF3: 3 | AG3: Reducing waiting time, Workspace layout (how space is divided between me and the robot), Working at a comfortable pace, Robot’s limitations for certain tasks, Let the robot do the work | AH3: Limitations of the robot | AI3: Quite nice, but hopefully can be do more soon | AJ3: No, it was able to do the simple tasks | AK3: Yes, seemed good. I let the robot do the collaboration tasks first and then the robot only tasks. | AL3: Yes, could use time for something else | AM3: No, he is my work assistant | AN3: safe time for me | AO3: First, I thought optimizing the overal performance, then reducing my workload | AP3: I would not reallocate the tasks, but focus on iterative steps on improving the collaboration. I need to understand the capabilities of the robot first, before assigning tasks to it.
A4: Performed pretty good in both, check the TA for task steps | B4: P13 | C4: 30 | D4: 62 | E4: =TA_NQY!F10+TA_NQO!F10 -> 265 | F4: 300 | G4: =TA_NQY!G10+TA_NQO!G10 -> 14 | H4: 14 | I4: 3 | J4: 9 | K4: 6 | L4: 7 | M4: 8 | N4: 9 | O4: 4 | P4: 10 | Q4: 4 | R4: 7 | S4: 7 | T4: 5 | U4: 8 | V4: 10 | W4: 8 | X4: 10 | Y4: 6 | Z4: 10 | AA4: 3 | AB4: 10 | AC4: 10 | AD4: 10 | AE4: 4 | AF4: 5 | AG4: Reducing waiting time, Reducing total completion time | AH4: Previous tasks where the human had to do the job, where assiged to the robot, in order to work in parallel. | AI4: They were sufficient and helpful to work in parallel | AJ4: Not after doing it several times. But untrained for sure at all tasks. | AK4: Yes | AL4: Yes | AM4: It was like working with a partner. | AN4: The certainty of completing the task. Setting the first step so I can build on it and at the same time the robot can do further tasks, where I again can contribute. | AO4: No. I pro robot | AP4: The last run was perfect for me. The robot first needs to place the buildings where i can work on it. So i never have to wait for the robot.
A5: lack of skill with questions, in physical mode, performed good | B5: P15 | C5: 32 | D5: 73 | E5: =TA_NQY!F12+TA_NQO!F12 -> 244 | F5: 668 | G5: =TA_NQY!G12+TA_NQO!G12 -> 10 | H5: 17 | I5: 3 | J5: 7 | K5: 6 | L5: 4 | M5: 6 | N5: 5 | O5: 10 | P5: 6 | Q5: 6 | R5: 6 | S5: 3 | T5: 5 | U5: 9 | V5: 7 | W5: 10 | X5: 10 | Y5: 8 | Z5: 7 | AA5: 8 | AB5: 6 | AC5: 10 | AD5: 10 | AE5: 6 | AF5: 7 | AG5: Reducing total completion time | AH5: which is going to be faster | AI5: robot perform really good | AJ5: individually no, maybe robot is better at math | AK5: yes | AL5: yes | AM5: im in the lead, i would consider the robot a tool not a team mate | AN5: what can the robot do whitout stopping. | AO5: no | AP5: would be interesting to see if the robot can solve the math problems and if i can also allocate the math problems to the robot, what I would choose
A6: Average, Check if he kept same TA in both | B6: P17 | C6: 30 | D6: 69 | E6: =TA_NQY!F14+TA_NQO!F14 -> 343 | F6: 387 | G6: =TA_NQY!G14+TA_NQO!G14 -> 20 | H6: 20 | I6: 2 | J6: 5 | K6: 3 | L6: 3 | M6: 3 | N6: 5 | O6: 9 | P6: 10 | Q6: 3 | R6: 6 | S6: 1 | T6: 1 | U6: 10 | V6: 10 | W6: 10 | X6: 10 | Y6: 10 | Z6: 9 | AA6: 10 | AB6: 10 | AC6: 10 | AD6: 10 | AE6: 4 | AF6: 7 | AG6: Reducing waiting time, Reducing total completion time, Workspace layout (how space is divided between me and the robot), Robot’s limitations for certain tasks | AH6: I tried to maximiye parallel tasks. | AI6: It would be great if it could do the screw task. | AJ6: no | AK6: zes | AL6: if it was faster yes. | AM6: I was the lead. | AN6: Speed and movement direction. | AO6: yes when I found out how high it brings the objects. I tried to avoid being on its way by changing task order. | AP6: I would give the last parts of hostpital to myself because the robot did not align them well.
A7: with question mode, gave less tasks to the robot | B7: P19 | C7: 33 | D7: 57 | E7: =TA_NQY!F17+TA_NQO!F17 -> 287 | F7: 359 | G7: =TA_NQY!G17+TA_NQO!G17 -> 17 | H7: 16 | I7: 4 | J7: 8 | K7: 6 | L7: 5 | M7: 6 | N7: 7 | O7: 9 | P7: 9 | Q7: 5 | R7: 7 | S7: 1 | T7: 2 | U7: 8 | V7: 9 | W7: 9 | X7: 6 | Y7: 8 | Z7: 9 | AA7: 8 | AB7: 9 | AC7: 8 | AD7: 8 | AE7: 6 | AF7: 7 | AG7: Reducing waiting time, Reducing total completion time, Workspace layout (how space is divided between me and the robot), My own performance/abilities | AH7: With the reasons mentioned above and the mock tries before the main experiment. | AI7: I believe there is room for improvments as in doing more difficults tasks and make the task devition more fair. | AJ7: No, everything could actually be done easily as a human, but in the matter of collaboration, it did help with the time efficiency. | AK7: the last time yes, but as in fairness of task allocation, I belive it could learn more things to do. | AL7: Yes definatly. | AM7: The last round yes I would say. but overall I felt like allocation of the tasks, answering the pop up questions, and also working on the main tasks puts you kinda in a leading position, and also being aware of the position and the doings of the robat. | AN7: Speed, Movement and positioning | AO7: Yes, the last round I was happy that i caculated its speed and movement, therefore I felt we were working more as one, rather than just waiting for each other. | AP7: Nothing really, I feel like I found the best task allocation combination for both of us.
A8: with question mode, gave less tasks to the robot | B8: P21 | C8: 29 | D8: 66 | E8: =TA_NQY!F19+TA_NQO!F19 -> 401 | F8: 472 | G8: =TA_NQY!G19+TA_NQO!G19 -> 22 | H8: 19 | I8: 2 | J8: 6 | K8: 2 | L8: 4 | M8: 2 | N8: 7 | O8: 9 | P8: 7 | Q8: 4 | R8: 7 | S8: 1 | T8: 3 | U8: 8 | V8: 7 | W8: 3 | X8: 2 | Y8: 8 | Z8: 6 | AA8: 8 | AB8: 6 | AC8: 8 | AD8: 9 | AE8: 2 | AF8: 2 | AG8: Reducing waiting time, Reducing total completion time | AH8: I tried to assign as many tasks to the robot as possible | AI8: It is performing most of its assigned tasks well. | AJ8: No | AK8: Yes | AL8: Yes, many times the robot finished its assigned before I could finish mine | AM8: The robot behaves dominant during the task, as it does not wait for the human to finish his or her task to avoid collisions. | AN8: The amount of tasks it is capable to perform. | AO8: No | AP8: Yes, I would change the order. So that the human has to wait only as little as possible to start with the tasks assigned.
A9: safety and ability as reason | B9: P22 | C9: 38 | D9: 61 | E9: =TA_NQY!F20+TA_NQO!F20 -> 346 | F9: 396 | G9: =TA_NQY!G20+TA_NQO!G20 -> 20 | H9: 22 | I9: 2 | J9: 3 | K9: 2 | L9: 3 | M9: 2 | N9: 5 | O9: 9 | P9: 9 | Q9: 3 | R9: 6 | S9: 1 | T9: 1 | U9: 9 | V9: 9 | W9: 8 | X9: 7 | Y9: 8 | Z9: 7 | AA9: 8 | AB9: 7 | AC9: 10 | AD9: 10 | AE9: 2 | AF9: 2 | AG9: My own performance/abilities, Robot’s limitations for certain tasks, My safety (avoiding collisions with the robot) | AH9: After experimenting with the robot, I found that for example It woulkd be more efficient for me if I do the Wheel task by myself. | AI9: I thought it is quite interesting what he is capable of doing and it would make thing more efficient or easy if thez are implementet in some tasks or activities. | AJ9: Not really, I mean I can also place the things in their forms. The Robot also took its time to place the figures and sometimes they are not quite fix placed. | AK9: Yes, it did. It felt alright, like a team work | AL9: Sure, I think so. | AM9: It felt like a teamworked, while I was busy doing some tasks, he managed to do the rest. | AN9: It was more the position of the Bilduing rather than the Robot capacities. The way he moved also influenced wether I should start with a task or another. | AO9: No, I think it is useful and could be really nice id in the future could do more things. | AP9: Mazbe the position of the Wheel and the Hospital. If you want the robot to do most of the things but zou also want to be readz with your tasks, then you will probablz start with these 2 task, but because they are to aproximated to each other, it is kind of difficult to work wihtout colliding with the robot.
A10: gave all task to robot | B10: P23 | C10: 34 | D10: 65 | E10: =TA_NQY!F21+TA_NQO!F21 -> 409 | F10: 402 | G10: =TA_NQY!G21+TA_NQO!G21 -> 22 | H10: 22 | I10: 8 | J10: 4 | K10: 3 | L10: 3 | M10: 8 | N10: 4 | O10: 10 | P10: 10 | Q10: 3 | R10: 10 | S10: 8 | T10: 3 | U10: 10 | V10: 10 | W10: 10 | X10: 10 | Y10: 10 | Z10: 9 | AA10: 10 | AB10: 10 | AC10: 9 | AD10: 10 | AE10: 1 | AF10: 1 | AG10: Reducing waiting time, Reducing total completion time, Workspace layout (how space is divided between me and the robot), Working at a comfortable pace, Robot’s limitations for certain tasks, My safety (avoiding collisions with the robot) | AH10: If robot can do the tasks, than assign to robot. | AI10: Supporting task, ex. Holding a block during screwing or putting the blocks on the right place. avoiding colisions with my arms. | AJ10: yes, at the beginnig of the expereiment. Because I needed to unterstand the building process and it tooks some time at first. | AK10: yes. There was clear definition of which tasks can be done with robots and human. | AL10: yes, certainly, ex. Screwing or Cliking (?) of the Snap. | AM10: I felt I was the lead because I had to controlled and mangend the path of my amrs to avoid a collisions or checked in which stage the robot is working. | AN10: Capability of the Robot - Can robot do this? | AO10: yes, more positive | AP10: I would rellocate the tasks in the order of the position of the blocks > Robot puts the blocks from front to back so I can screw the Wheel and the hospital without collisions with the robot.
A11: gave all task to robot and knows it | B11: P24 | C11: 34 | D11: 62 | E11: =TA_NQY!F22+TA_NQO!F22 -> 370 | F11: 561 | G11: =TA_NQY!G22+TA_NQO!G22 -> 22 | H11: 22 | I11: 1 | J11: 3 | K11: 4 | L11: 3 | M11: 3 | N11: 4 | O11: 3 | P11: 8 | Q11: 1 | R11: 5 | S11: 1 | T11: 7 | U11: 3 | V11: 6 | W11: 2 | X11: 7 | Y11: 4 | Z11: 5 | AA11: 4 | AB11: 3 | AC11: 1 | AD11: 1 | AE11: 1 | AF11: 1 | AG11: more tasks for robot and less for me | AH11: assign to robot as much as possible | AI11: safe enough but very slow | AJ11: nope | AK11: no | AL11: no | AM11: team working: yes, lead robot: so so | AN11: no specific quality, I prefer to perfom less tasks | AO11: yes, it executed tasks slowly | AP11: maybe less tasks to robot
A12: with question mode, gave less tasks to the robot but perfomed better | B12: P25 | C12: 32 | D12: 72 | E12: =TA_NQY!F23+TA_NQO!F23 -> 335 | F12: 300 | G12: =TA_NQY!G23+TA_NQO!G23 -> 20 | H12: 18 | I12: 2 | J12: 4 | K12: 2 | L12: 2 | M12: 2 | N12: 5 | O12: 10 | P12: 8 | Q12: 2 | R12: 5 | S12: 1 | T12: 3 | U12: 10 | V12: 10 | W12: 8 | X12: 9 | Y12: 8 | Z12: 9 | AA12: 7 | AB12: 8 | AC12: 10 | AD12: 10 | AE12: 7 | AF12: 8 | AG12: Reducing waiting time, Reducing total completion time, Workspace layout (how space is divided between me and the robot), Robot’s limitations for certain tasks | AH12: I tried to allocate the tasks in a way that both the robot and I had something to do at all times. Usually i did the more complex tasks, while the robot did things where it only had to place the buildings. | AI12: It was capable of everything it was assigned to do, however some things were just faster to do by myself. I thought the robot could also to some of the screws but i am aware that this is more complex since it can´t really place the screw and screw it in at the same time. | AJ12: Yes, it was faster at finding the blocks and where to put them. Although i also got faster at it while completing the experiment more often. | AK12: yes | AL12: yes, but i would still want the total time to be minimal so I would take that into consideration | AM12: yes | AN12: The fact that it doesnt do any screwing and, i also tried to the tasks that requires more "complex" movement as these take rather long. | AO12: no | AP12: Maybe I would place something myself to at the end so i am not watching the robot finsish while doing nothing.
A13: randomly assigned | B13: P26 | C13: 24 | D13: 66 | E13: =TA_NQY!F24+TA_NQO!F24 -> 305 | F13: 410 | G13: =TA_NQY!G24+TA_NQO!G24 -> 16 | H13: 16 | I13: 8 | J13: 7 | K13: 8 | L13: 9 | M13: 9 | N13: 8 | O13: 9 | P13: 10 | Q13: 8 | R13: 7 | S13: 1 | T13: 2 | U13: 9 | V13: 9 | W13: 10 | X13: 10 | Y13: 10 | Z13: 9 | AA13: 10 | AB13: 9 | AC13: 9 | AD13: 9 | AE13: 3 | AF13: 4 | AG13: Random choice, Reducing waiting time, Robot’s limitations for certain tasks | AH13: In couple of tasks random, for the others considered waiting time for efficiency | AI13: Good, just it could be better for putting parts in the places more precisely. | AJ13: Yes, for some parts I was mixing the directions, e.g. hospital. The robots could put it faster than me. | AK13: Yes. | AL13: Exactly. I allocated some parts to me since I saw that it was more difficult to put it precisely. | AM13: I can consider. Just I should check afterwards what the robot completed whether it is correct. | AN13: The interlocking of two parts, e.g. dovetail | AO13: Yes, I was not sure how we could collaborate together while assembling two pieces together closely like in the hospital part. But surprisingly got used to work with it. | AP13: I wouldn't work with him on the same task; I would allocate him tasks that I wasn't involved in. This slowed me down more than it should have.
A14: gave few tasks to robot but perfomed well | B14: P29 | C14: 37 | D14: 56 | E14: =TA_NQY!F27+TA_NQO!F27 -> 240 | F14: 260 | G14: =TA_NQY!G27+TA_NQO!G27 -> 11 | H14: 12 | I14: 2 | J14: 4 | K14: 2 | L14: 2 | M14: 3 | N14: 5 | O14: 10 | P14: 10 | Q14: 3 | R14: 5 | S14: 1 | T14: 1 | U14: 10 | V14: 10 | W14: 10 | X14: 10 | Y14: 10 | Z14: 10 | AA14: 10 | AB14: 10 | AC14: 10 | AD14: 10 | AE14: 4 | AF14: 4 | AG14: Reducing waiting time, Reducing total completion time, My own performance/abilities, Robot’s limitations for certain tasks | AH14: If I can finish the task before in time so he can start with the following aready, or calculating in some buffer time to answer some questions. | AI14: He can offload task but cant do them better | AJ14: No, he was there to paralellisiese the task while I had to answer questions or so | AK14: For me yes, but it was not equal for both | AL14: No he is not more capable | AM14: I was the lead | AN14: Speed | AO14: No | AP14: No everything worked out perfectly
A15: check for ta if it's the same | B15: P31 | C15: 26 | D15: 72 | E15: =TA_NQY!F29+TA_NQO!F29 -> 387 | F15: 371 | G15: =TA_NQY!G29+TA_NQO!G29 -> 17 | H15: 17 | I15: 3 | J15: 6 | K15: 2 | L15: 2 | M15: 5 | N15: 5 | O15: 10 | P15: 9 | Q15: 6 | R15: 4 | S15: 4 | T15: 7 | U15: 10 | V15: 8 | W15: 6 | X15: 8 | Y15: 9 | Z15: 8 | AA15: 9 | AB15: 7 | AC15: 9 | AD15: 10 | AE15: 8 | AF15: 9 | AG15: Reducing waiting time, Reducing total completion time, Robot’s limitations for certain tasks | AH15: Tried to think about how long it takes me and the robot to complete a task, and then assign the tasks such that we both finish at the same time in the end, maximizing efficiency. | AI15: Something that I forgot to take into account is how precise the robot is, meaning that although it does not move as fast, the movement it does is calculated and does not waste time. | AJ15: Maybe sliding the dovetail upper part in, it seemed strangely efficient at that. | AK15: For the most part, yes. | AL15: Definitely. | AM15: I felt like a team, maybe even as if the robot was the lead on some occassions, as it always finished before me. | AN15: Probably the fact that that it is not able to do the screwing parts. | AO15: It did, in the beginning I did not assign as many tasks to it, as I thought that I will be faster than the robot. By the last experiment I basically almost allocated all the tasks the robot could do to it. | AP15: I think moving the wheel holder placement higher, as during the last run I was waiting a bit too long for that to be placed. Except that, I believe the allocation was fine.
A16: normal | B16: P32 | C16: 39 | D16: 68 | E16: =TA_NQY!F30+TA_NQO!F30 -> 311 | F16: 417 | G16: =TA_NQY!G30+TA_NQO!G30 -> 18 | H16: 20 | I16: 2 | J16: 4 | K16: 2 | L16: 2 | M16: 3 | N16: 6 | O16: 10 | P16: 10 | Q16: 5 | R16: 7 | S16: 3 | T16: 5 | U16: 10 | V16: 9 | W16: 10 | X16: 9 | Y16: 10 | Z16: 8 | AA16: 10 | AB16: 9 | AC16: 9 | AD16: 9 | AE16: 6 | AF16: 7 | AG16: Reducing waiting time, Workspace layout (how space is divided between me and the robot), Robot’s limitations for certain tasks, My safety (avoiding collisions with the robot) | AH16: Based on the experienced waiting time | AI16: Keeping the pace. precision | AJ16: Precision of placement, no error in orders | AK16: yes | AL16: yes | AM16: yes, we are a team | AN16: the limitations and the safety in the workspace | AO16: no, it was positive from beginning | AP16: The last allocation of tasks was optimal, minimum stall time for me and robot, safety in the mvements
A17: for second experiment with Q performed better | B17: P33 | C17: 31 | D17: 64 | E17: =TA_NQY!F31+TA_NQO!F31 -> 298 | F17: 281 | G17: =TA_NQY!G31+TA_NQO!G31 -> 17 | H17: 16 | I17: 6 | J17: 9 | K17: 3 | L17: 4 | M17: 3 | N17: 7 | O17: 10 | P17: 9 | Q17: 8 | R17: 9 | S17: 8 | T17: 4 | U17: 7 | V17: 8 | W17: 8 | X17: 9 | Y17: 6 | Z17: 10 | AA17: 6 | AB17: 9 | AC17: 8 | AD17: 10 | AE17: 8 | AF17: 10 | AG17: Reducing waiting time, Workspace layout (how space is divided between me and the robot), Robot’s limitations for certain tasks | AH17: Taking into account the pop-up questions helped with the waiting times for the robot, as if timed correctly the questions can basically mask the time spent waiting for the robot to complete its tasks. Otherwise, the robot is fairly slow with picking up and placing the pieces, so complex parts can be shifted to be mostly done by humans, or in the case of the museum, the robot was not properly placing the piece. | AI17: It is ok, but I would prefer it if it were doing the screwing and detailed tasks like passing the rod through the buildings, as I feel it's were most of the effort is. | AJ17: No | AK17: Somewhat, once the paths of the robot are fixed and well-known it is easier to work around it | AL17: Definitely, especially for screwing | AM17: It felt more like the robot was helping me, rather than working together, also because the robot was not getting the pop-up questions | AN17: Its slowness | AO17: With the pop-up questions it actually improved a bit, because its slowness was on-par with the context switching for taking care of the pop-up questions | AP17: I am fairly satisfied with how I placed the tasks for the pop-up questions, so nothing
A18: gave all to the robot, perfomed bad | B18: P35 | C18: 34 | D18: 71 | E18: =TA_NQY!F33+TA_NQO!F33 -> 383 | F18: 392 | G18: =TA_NQY!G33+TA_NQO!G33 -> 22 | H18: 22 | I18: 3 | J18: 4 | K18: 3 | L18: 3 | M18: 4 | N18: 4 | O18: 10 | P18: 9 | Q18: 3 | R18: 4 | S18: 1 | T18: 2 | U18: 9 | V18: 9 | W18: 10 | X18: 10 | Y18: 10 | Z18: 10 | AA18: 10 | AB18: 10 | AC18: 10 | AD18: 9 | AE18: 2 | AF18: 2 | AG18: Reducing total completion time, My own performance/abilities, Robot’s limitations for certain tasks | AH18: most demanding tasks at first, then the robot does the work | AI18: Very good, but could be quicker | AJ18: no | AK18: yes | AL18: yes | AM18: yes, team | AN18: Moving parts to the right place, when it makes the most sense | AO18: no | AP18: actually nothing
A24: CATEGORY:
A25: normal | B25: many | D25: 15
A26: lack of skill in mental load, but good in physical | B26: P15 | C26: normal | D26: -
A27: didn’t aim for optimization but performed normal | B27: P22,P26 | C27: normal | D27: -
A28: gave few tasks to robot but performed good | B28: P29 | C28: normal | D28: -
A29: in second experiment with Q, gave less to robot and performed better | B29: P25, P33 | D29: 2
A30: in second experiment with Q, gave less to robot and performed normal | B30: P19,P21 | D30: 2
A31: in second experiment without Q got chilled | B31: P12 | D31: 1
A32: Gave all the tasks to the robot | B32: P23, P24,P35 | D32: 3
A33: Gave same amount of tasks to the robot in both scenarios | B33: P13, P17, P31 | D33: 3

Sheet pattern_normal
B1: Demographics | G1: Self Assesment | Q1: General Attitude toward robots | AO1: Nasa TLX | BB1: Nasa TlX | BS1: Post experiment
A2: Timestamp | B2: Participant ID: | C2: Gender | D2: Age | E2: Have you ever had any experience cooperating or interacting with a robot before this experiment? | F2: 1- Is the robot’s presence pleasant to you? | G2: 1- I can always manage to solve difficult problems if I try hard enough. | H2: 2- If someone opposes me, I can find the means and ways to get what I want. | I2: 3- It is easy for me to stick to my aims and accomplish my goals. | J2: 4- I am confident that I could deal efficiently with unexpected events. | K2: 5- Thanks to my resourcefulness, I know how to handle unforeseen situations. | L2: 6- I can solve most problems if I invest the necessary effort. | M2: 7- I can remain calm when facing difficulties because I can rely on my coping abilities. | N2: 8- When I am confronted with a problem, I can usually find several solutions. | O2: 9- If I am in trouble, I can usually think of a solution. | P2: 10- I can usually handle whatever comes my way. | Q2: Mean | R2: SUM | S2: 1- I can trust persons and organizations related to development of robots | T2: 2- Persons and organizations related to development of robots will consider the needs, thoughts and feelings of their users | U2: 3- I can trust a robot | V2: 4- I would feel relaxed talking with a robot | W2: 5- If robots had emotions, I would be able to be friend with them | X2: 6- I would feel uneasy if I was given a job where I had to use robots | Y2: 7- I fear that a robot would not understand my commands | Z2: 8- Robots scare me | AA2: 9- I would feel very nervous just being around a robot | AB2: 10- I don’t want a robot to touch me | AC2: 11- Robots are necessary because they can do jobs that are too hard or too dangerous for people | AD2: 12- Robots can make life easier | AE2: 13- Assigning routine tasks to robots lets people do more meaningful tasks | AF2: 14- Dangerous tasks should primarily be given to robots | AG2: 15- Robots are a good thing for society, because they help people | AH2: 16- Robots may make us even lazier | AI2: 17- Widespread use of robots is going to take away jobs from people | AJ2: 18- I am afraid that robots will encourage less interaction between humans | AK2: 19- Robotics is one of the areas of technology that needs to be closely monitored | AL2: 20- Unregulated use of robotics can lead to societal upheavals | AM2: Sum( reversed negative values) | AN2: Personal positive | AO2: Personal negative | AP2: Social Posiitve | AQ2: Social negative | AR2: Please indicate the scenario you just completed: | AS2: TA Time_NQ | AT2: Assembly time | AU2: Robot N_task | AV2: 1.) Mental Demand: How much thinking, deciding, or calculating was required to perform the tasks? | AW2: 2.) Physical Demand: How much physical activity was required to perform the tasks? | AX2: 3.) Temporal Demand: How hurried or rushed was the pace of the tasks? | AY2: 4.) Performance: How successful were you in accomplishing what you were asked to do? | AZ2: 5.) Effort: How hard did you have to work to accomplish and maintain your level of performance? | BA2: 6.) Frustration: How insecure, discouraged, irritated, stressed, and annoyed were you? | BB2: 7.) Satisfaction: How satisfied were you with the outcome of the collaboration. | BC2: 8.) Fairness: How fair do you think your task allocation was? | BD2: 9.) Efficency: How efficient your task allocation was? | BE2: 10.) Task Allocation: How satisfied are you with your task allocation? | BF2: 11.) Willingness: Are you willing to collaborate with this robot on more important tasks? | BG2: 12.) Decision-Making: How difficult was it to decide which tasks to assign to yourself versus the robot? | BH2: Please indicate the scenario you just completed: | BI2: Assembly time with question | BJ2: Robot N_task With question | BK2: 1.) Mental Demand: How much thinking, deciding, or calculating was required to perform the tasks?2 | BL2: 2.) Physical Demand: How much physical activity was required to perform the tasks? 3 | BM2: 3.) Temporal Demand: How hurried or rushed was the pace of the tasks?4 | BN2: 4.) Performance: How successful were you in accomplishing what you were asked to do?5 | BO2: 5.) Effort: How hard did you have to work to accomplish and maintain your level of performance?6 | BP2: 6.) Frustration: How insecure, discouraged, irritated, stressed, and annoyed were you? 7 | BQ2: 7.) Satisfaction: How satisfied were you with the outcome of the collaboration.8 | BR2: 8.) Fairness: How fair do you think your task allocation was? 9 | BS2: 9.) Efficiency: How efficient your task allocation was? | BT2: 10.) Task Allocation: How satisfied are you with your task allocation?10 | BU2: 11.) Willingness: Are you willing to collaborate with this robot on more important tasks?11 | BV2: 12.) Decision-Making: How difficult was it to decide which tasks to assign to yourself versus the robot?12 | BW2: 1- What factors influenced how you assigned tasks between yourself and the robot? (Select all that apply) | BX2: 2- How did you decide whether to assign a task to yourself or the robot? | BY2: 3- What were your thoughts about the robot’s capabilities? | BZ2: 4- Did you feel the robot was better at any tasks than you? | CA2: 5- Did the collaboration feel balanced? | CB2: 6- Do you think if the robot was more capable you would allocate more tasks to it? | CC2: 7- Did you consider yourself and the robot as a team? Or did you feel you are the lead of it? | CD2: 8- What qualities of the robot influenced your allocation decisions? | CE2: 9- Did your opinion of the robot change during the task? | CF2: 10- If you could reallocate the tasks after this experience, what would you change and why?
A3: 45909.445 | B3: p11 | C3: Female | D3: 31 | E3: Yes | F3: 4 | G3: 4 | H3: 3 | I3: 4 | J3: 3 | K3: 2 | L3: 4 | M3: 2 | N3: 3 | O3: 4 | P3: 3 | Q3: =Form_Responses[[#This Row],[SUM]]/10 -> 3.1 | R3: =SUM(Form_Responses[[#This Row],[1- I can always manage to solve difficult problems if I try hard enough.]:[10- I can usually handle whatever comes my way.]]) -> 31 | S3: 5 | T3: 5 | U3: 5 | V3: 5 | W3: 5 | X3: 1 | Y3: 1 | Z3: 1 | AA3: 1 | AB3: 1 | AC3: 5 | AD3: 5 | AE3: 5 | AF3: 5 | AG3: 4 | AH3: 4 | AI3: 4 | AJ3: 4 | AK3: 5 | AL3: 4 | AM3: =60+SUM(Form_Responses[[#This Row],[11- Robots are necessary because they can do jobs that are too hard or too dangerous for people ]:[15- Robots are a good thing for society, because they help people]])-SUM(Form_Responses[[#This Row],[16- Robots may make us even lazier ]:[20- Unregulated use of robotics can lead to societal upheavals]]) -> 64 | AN3: =SUM(Form_Responses[[#This Row],[1- I can trust persons and organizations related to development of robots ]:[5- If robots had emotions, I would be able to be friend with them]]) -> 10 | AO3: =SUM(Form_Responses[[#This Row],[6- I would feel uneasy if I was given a job where I had to use robots]:[10- I don’t want a robot to touch me]]) -> 9 | AP3: =SUM(Form_Responses[[#This Row],[11- Robots are necessary because they can do jobs that are too hard or too dangerous for people ]:[15- Robots are a good thing for society, because they help people]]) -> 22 | AQ3: =SUM(Form_Responses[[#This Row],[16- Robots may make us even lazier ]:[20- Unregulated use of robotics can lead to societal upheavals]]) -> 18 | AR3: Without pop-up questions | AS3: =TA_NQY!F3+TA_NQO!F3 -> 332 | AT3: =TA_NQY!F8+TA_NQO!F8 -> 347 | AU3: =TA_NQY!G8+TA_NQO!G8 -> 19 | AV3: 4 | AW3: 7 | AX3: 6 | AY3: 10 | AZ3: 7 | BA3: 6 | BB3: 10 | BC3: 10 | BD3: 9 | BE3: 9 | BF3: 10 | BG3: 4 | BH3: With pop-up questions | BI3: =TA_QY!F8+TA_QO!F8 -> 581 | BJ3: =TA_QY!G8+TA_QO!G8 -> 21 | BK3: 10 | BL3: 9 | BM3: 8 | BN3: 10 | BO3: 9 | BP3: 9 | BQ3: 9 | BR3: 8 | BS3: 9 | BT3: 9 | BU3: 10 | BV3: 10 | BW3: Reducing waiting time, Reducing total completion time | BX3: Not to wait for robot, but whith pop up questions it was much more complicated. | BY3: It was good, I liked how it was doing dovetail uper parts. | BZ3: No, but when I needed to think for questions it was better. | CA3: Yes, I feel if I had one more round it could be optimized in both set up. | CB3: Yes, probably doing screw with nuts. | CC3: more like a team that I needed to adjust my moves to it and when is the optimom time to do the task and not to crash. | CD3: low pace of robot made me sometimes change the allocations | CE3: no | CF3: for without question I do wheel myself and second part of bridge and second part of hospital, for with questions just I do the second part of hospital and the rest with robot.
A4: 45909.613 | B4: P14 | C4: Female | D4: 26 | E4: No | F4: 3 | G4: 3 | H4: 3 | I4: 2 | J4: 4 | K4: 4 | L4: 4 | M4: 4 | N4: 3 | O4: 4 | P4: 3 | Q4: =Form_Responses[[#This Row],[SUM]]/10 -> 3.3 | R4: =SUM(Form_Responses[[#This Row],[1- I can always manage to solve difficult problems if I try hard enough.]:[10- I can usually handle whatever comes my way.]]) -> 33 | S4: 3 | T4: 3 | U4: 4 | V4: 2 | W4: 3 | X4: 1 | Y4: 2 | Z4: 1 | AA4: 1 | AB4: 1 | AC4: 5 | AD4: 5 | AE4: 5 | AF4: 5 | AG4: 4 | AH4: 2 | AI4: 2 | AJ4: 1 | AK4: 4 | AL4: 2 | AM4: =60+SUM(Form_Responses[[#This Row],[11- Robots are necessary because they can do jobs that are too hard or too dangerous for people ]:[15- Robots are a good thing for society, because they help people]])-SUM(Form_Responses[[#This Row],[16- Robots may make us even lazier ]:[20- Unregulated use of robotics can lead to societal upheavals]]) -> 64 | AN4: =SUM(Form_Responses[[#This Row],[1- I can trust persons and organizations related to development of robots ]:[5- If robots had emotions, I would be able to be friend with them]]) -> 17 | AO4: =SUM(Form_Responses[[#This Row],[6- I would feel uneasy if I was given a job where I had to use robots]:[10- I don’t want a robot to touch me]]) -> 8 | AP4: =SUM(Form_Responses[[#This Row],[11- Robots are necessary because they can do jobs that are too hard or too dangerous for people ]:[15- Robots are a good thing for society, because they help people]]) -> 23 | AQ4: =SUM(Form_Responses[[#This Row],[16- Robots may make us even lazier ]:[20- Unregulated use of robotics can lead to societal upheavals]]) -> 19 | AR4: Without pop-up questions | AS4: =TA_NQY!F4+TA_NQO!F4 -> 384 | AT4: =TA_NQY!F11+TA_NQO!F11 -> 311 | AU4: =TA_NQY!G11+TA_NQO!G11 -> 19 | AV4: 2 | AW4: 2 | AX4: 2 | AY4: 8 | AZ4: 3 | BA4: 1 | BB4: 9 | BC4: 6 | BD4: 4 | BE4: 7 | BF4: 10 | BG4: 4 | BH4: With pop-up questions | BI4: =TA_QY!F11+TA_QO!F11 -> 374 | BJ4: =TA_QY!G11+TA_QO!G11 -> 22 | BK4: 5 | BL4: 3 | BM4: 4 | BN4: 7 | BO4: 4 | BP4: 1 | BQ4: 9 | BR4: 8 | BS4: 8 | BT4: 8 | BU4: 8 | BV4: 3 | BW4: Reducing waiting time, Reducing total completion time, Robot’s limitations for certain tasks | BX4: Based on how fast I vs. the robot would be able to do it. | BY4: Very impresive, although the robot having to go back to its original starting location between tasks might be unefficient in more time sensitive tasks. | BZ4: More presiye and less prone to mistakes. While i might knock a building block with my arm while building, the robot does not. | CA4: Yes | CB4: No, I felt the robot was capable enough. | CC4: Yes, I felt we were a team. | CD4: The speed with which the robot would complete a task and whether or not if the robot was capable of it. | CE4: No. | CF4: I might try to divide the tasks between the robot and myself more to reduce my waiting time while the robot works.
